2025-02-06 22:36:24,268 - __main__ - INFO - Приложение запущено - c:\Users\roxfo\Desktop\Python\logging\Logger\LoggingV0.2\main.py:84
2025-02-06 22:36:24,269 - module_a - DEBUG - Запущена функция A - c:\Users\roxfo\Desktop\Python\logging\Logger\LoggingV0.2\module_a.py:6
2025-02-06 22:36:24,269 - module_b - ERROR - Ошибка из функции B - c:\Users\roxfo\Desktop\Python\logging\Logger\LoggingV0.2\module_b.py:8
2025-02-06 22:36:24,269 - module_a - INFO - Функция A завершена - c:\Users\roxfo\Desktop\Python\logging\Logger\LoggingV0.2\module_a.py:11
2025-02-06 22:36:24,270 - module_b - CRITICAL - Критическая ошибка в функции B - c:\Users\roxfo\Desktop\Python\logging\Logger\LoggingV0.2\module_b.py:9
2025-02-06 22:36:24,270 - asyncio - DEBUG - Using proactor: IocpProactor - C:\Users\roxfo\AppData\Local\Programs\Python\Python313\Lib\asyncio\proactor_events.py:631
2025-02-06 22:36:26,283 - async_worker - ERROR - Произошла ошибка: Что-то пошло не так! - c:\Users\roxfo\Desktop\Python\logging\Logger\LoggingV0.2\async_worker.py:18
2025-02-06 22:36:26,284 - __main__ - INFO - Приложение завершено - c:\Users\roxfo\Desktop\Python\logging\Logger\LoggingV0.2\main.py:100
